Workbook

Sheet Journal
A2: Type de frais | B2: Date du versement | C2: Montant en euro | D2: Case impôt | E2: Année | F2: Appartement | G2: Commentaire
A3: Janvier | C3: 550 | D3: 2033B-218
A4: Février | C4: 550 | D4: 2033B-218
A5: Mars | C5: 550 | D5: 2033B-218
A6: Avril | C6: 550 | D6: 2033B-218
A7: Mai | C7: 550 | D7: 2033B-218
A8: Juin | C8: 550 | D8: 2033B-218
A9: Juillet | C9: 550 | D9: 2033B-218
A10: Août | C10: 550 | D10: 2033B-218
A11: Septembre | C11: 550 | D11: 2033B-218
A12: Octobre | C12: 550 | D12: 2033B-218
A13: Novembre | C13: 550 | D13: 2033B-218
A14: Décembre | C14: 550 | D14: 2033B-218
A15: Sous-total | C15: =SUM(C3:C14) -> 6600
A16: Charge de copropriétés (récupérable et non récupérable) | C16: -160 | D16: 2033B-242
A17: Charge de copropriétés (récupérable et non récupérable) | C17: -160 | D17: 2033B-242
A18: Charge de copropriétés (récupérable et non récupérable) | C18: -160 | D18: 2033B-242
A19: Charge de copropriétés (récupérable et non récupérable) | C19: -160 | D19: 2033B-242
A20: Taxe foncière | C20: -568 | D20: 2033B-244
A21: CFE (Cotisation foncière des entreprises) | C21: -300 | D21: 2033B-244
A22: Assurance | C22: -100 | D22: 2033B-242
A23: Intérêts de crédit immobilier | C23: -768 | D23: 2033B-294
A24: Assurance du crédit immobilier | D24: 2033B-294
A25: Electricité | C25: -720 | D25: 2033B-242?
A26: Internet | C26: -250 | D26: 2033B-242?
A27: Ammortissement | C27: =-Amortissement!F12 -> -3258.6667 | D27: 2033C-572 et 2033B-254
A28: Sous-total | C28: =SUM(C16:C27) -> -6604.6667

Sheet Amortissement
A2: Estimation du prix de l'appartement | B2: 104000
A3: Base amortissable | B3: =B2-D6 -> 88400
A4: Date de début d'activité | B4: 44927
C5: Durée de l'ammortissement en année | D5: Immobilisation | E5: Case impôt | F5: Ammortissement | G5: Restant à amortir | H5: Case impôt
A6: Prix du terrain (15%) (non amortissable) | B6: 0.15 | D6: =(0.15)*B2 -> 15600
A7: Structure (Gros œuvre) | B7: 0.25 | C7: 50 | D7: =B7*($B$2) -> 26000 | E7: 2033C-432 (Construction) Faire la somme Structure + Facade | F7: =D7/C7 -> 520 | G7: =D7-F7 -> 25480 | H7: 2033C-522
A8: Façade | B8: 0.2 | C8: 40 | D8: =B8*($B$2) -> 20800 | F8: =D8/C8 -> 520 | G8: =D8-F8 -> 20280 | H8: 2033C-522
A9: Equipement | B9: 0.2 | C9: 25 | D9: =B9*($B$2) -> 20800 | E9: 2033C-442 (Installation technique, matériel et outillage) IGT | F9: =D9/C9 -> 832 | G9: =D9-F9 -> 19968 | H9: 2033C-532
A10: Agencement (Cloisons, platreries, élec, etc.) | B10: 0.2 | C10: 15 | D10: =B10*($B$2) -> 20800 | E10: 2033C-452 (Installation générale, agencement divers) | F10: =D10/C10 -> 1386.6667 | G10: =D10-F10 -> 19413.333 | H10: 2033C-542
A11: Mobilier | C11: 10 | E11: 2033C-472 | H11: 2033C-562
C12: Total | D12: =SUM(D6:D10) -> 104000 | F12: =SUM(F7:F11) -> 3258.6667 | G12: =SUM(G7:G11) -> 85141.333 | H12: 2033C-572
A14: Tableau d'amortissement | B14: Structure | C14: Facade | D14: Equipement | E14: Agencement | F14: Mobilier | G14: Total
A15: Année
A16: 2023 | B16: =F7 -> 520 | C16: =$F$8 -> 520 | D16: =$F$9 -> 832 | E16: =$F$10 -> 1386.6667 | G16: =SUM(B16:F16) -> 3258.6667
A17: 2024 | B17: =F7 -> 520 | C17: =$F$8 -> 520 | D17: =$F$9 -> 832 | E17: =$F$10 -> 1386.6667 | G17: =SUM(B17:F17) -> 3258.6667
A18: 2025 | B18: =F7 -> 520 | C18: =$F$8 -> 520 | D18: =$F$9 -> 832 | E18: =$F$10 -> 1386.6667 | G18: =SUM(B18:F18) -> 3258.6667
A19: 2026 | B19: =$F$7 -> 520 | C19: =$F$8 -> 520 | D19: =$F$9 -> 832 | E19: =$F$10 -> 1386.6667 | G19: =SUM(B19:F19) -> 3258.6667
A20: 2027 | B20: =$F$7 -> 520 | C20: =$F$8 -> 520 | D20: =$F$9 -> 832 | E20: =$F$10 -> 1386.6667 | G20: =SUM(B20:F20) -> 3258.6667
A21: 2028 | B21: =$F$7 -> 520 | C21: =$F$8 -> 520 | D21: =$F$9 -> 832 | E21: =$F$10 -> 1386.6667 | G21: =SUM(B21:F21) -> 3258.6667
A22: 2029 | B22: =$F$7 -> 520 | C22: =$F$8 -> 520 | D22: =$F$9 -> 832 | E22: =$F$10 -> 1386.6667 | G22: =SUM(B22:F22) -> 3258.6667
A23: 2030 | B23: =$F$7 -> 520 | C23: =$F$8 -> 520 | D23: =$F$9 -> 832 | E23: =$F$10 -> 1386.6667 | G23: =SUM(B23:F23) -> 3258.6667
A24: 2031 | B24: =$F$7 -> 520 | C24: =$F$8 -> 520 | D24: =$F$9 -> 832 | E24: =$F$10 -> 1386.6667 | G24: =SUM(B24:F24) -> 3258.6667
A25: 2032 | B25: =$F$7 -> 520 | C25: =$F$8 -> 520 | D25: =$F$9 -> 832 | E25: =$F$10 -> 1386.6667 | G25: =SUM(B25:F25) -> 3258.6667
A26: 2033 | B26: =$F$7 -> 520 | C26: =$F$8 -> 520 | D26: =$F$9 -> 832 | E26: =$F$10 -> 1386.6667 | G26: =SUM(B26:F26) -> 3258.6667
A27: 2034 | B27: =$F$7 -> 520 | C27: =$F$8 -> 520 | D27: =$F$9 -> 832 | E27: =$F$10 -> 1386.6667 | G27: =SUM(B27:F27) -> 3258.6667
A28: 2035 | B28: =$F$7 -> 520 | C28: =$F$8 -> 520 | D28: =$F$9 -> 832 | E28: =$F$10 -> 1386.6667 | G28: =SUM(B28:F28) -> 3258.6667
A29: 2036 | B29: =$F$7 -> 520 | C29: =$F$8 -> 520 | D29: =$F$9 -> 832 | E29: =$F$10 -> 1386.6667 | G29: =SUM(B29:F29) -> 3258.6667
A30: 2037 | B30: =$F$7 -> 520 | C30: =$F$8 -> 520 | D30: =$F$9 -> 832 | E30: =$F$10 -> 1386.6667 | G30: =SUM(B30:F30) -> 3258.6667
A31: 2038 | B31: =$F$7 -> 520 | C31: =$F$8 -> 520 | D31: =$F$9 -> 832 | G31: =SUM(B31:F31) -> 1872
A32: 2039 | B32: =$F$7 -> 520 | C32: =$F$8 -> 520 | D32: =$F$9 -> 832 | G32: =SUM(B32:F32) -> 1872
A33: 2040 | B33: =$F$7 -> 520 | C33: =$F$8 -> 520 | D33: =$F$9 -> 832 | G33: =SUM(B33:F33) -> 1872
A34: 2041 | B34: =$F$7 -> 520 | C34: =$F$8 -> 520 | D34: =$F$9 -> 832 | G34: =SUM(B34:F34) -> 1872
A35: 2042 | B35: =$F$7 -> 520 | C35: =$F$8 -> 520 | D35: =$F$9 -> 832 | G35: =SUM(B35:F35) -> 1872
A36: 2043 | B36: =$F$7 -> 520 | C36: =$F$8 -> 520 | D36: =$F$9 -> 832 | G36: =SUM(B36:F36) -> 1872
A37: 2044 | B37: =$F$7 -> 520 | C37: =$F$8 -> 520 | D37: =$F$9 -> 832 | G37: =SUM(B37:F37) -> 1872
A38: 2045 | B38: =$F$7 -> 520 | C38: =$F$8 -> 520 | D38: =$F$9 -> 832 | G38: =SUM(B38:F38) -> 1872
A39: 2046 | B39: =$F$7 -> 520 | C39: =$F$8 -> 520 | D39: =$F$9 -> 832 | G39: =SUM(B39:F39) -> 1872
A40: 2047 | B40: =$F$7 -> 520 | C40: =$F$8 -> 520 | D40: =$F$9 -> 832 | G40: =SUM(B40:F40) -> 1872
A41: 2048 | B41: =$F$7 -> 520 | C41: =$F$8 -> 520 | G41: =SUM(B41:F41) -> 1040
A42: 2049 | B42: =$F$7 -> 520 | C42: =$F$8 -> 520 | G42: =SUM(B42:F42) -> 1040
...

Sheet Liasse fiscale N
D1: Brut | E1: Ammortissement | G1: Net Exercice N | I1: Bilan
A2: ACTIF | B2: Immobilisation corporelle | C2: 2033A-028 | D2: =J2 -> 88400 | E2: 2033A-030 | F2: =J3 -> -3258.6667 | G2: =D2+F2 -> 85141.333 | I2: Immobilisation brut - amortissement de l'année N | J2: =Amortissement!$B$3 -> 88400
I3: 2033C-572 et 2033B-254 | J3: =-Amortissement!$F$12 -> -3258.6667
I5: 2033B-218 | J5: =Journal!C15 -> 6600
B6: Disponibilité (La caisse/trésorerie) | C6: 2033A-084 | D6: =J10 -> 4224 | I6: 2033B-242 | J6: =Journal!C16+Journal!C17+Journal!C18+Journal!C19 -> -640
I7: 2033B-244 | J7: =Journal!C20+Journal!C21 -> -868
I8: 2033B-294 | J8: =Journal!C23+Journal!C24+Journal!C22 -> -868
B10: Total | D10: =D2+F2+D6 -> 89365.333 | I10: Disponibilité | J10: =SUM(J5:J8) -> 4224
A11: PASSIF | B11: Capital social | C11: 2033A-120 | D11: =D10-D13-D15 -> 20505 | I11: Résultat comptable (2033B-310) | J11: =SUM(J3:J8) -> 965.33333
B13: Résultat de l'exercice | C13: 2033A-136 | D13: =J11 -> 965.33333
B15: Dette (dette restant dû) | C15: 2033A-156 | D15: 67895 | I15: Résultat fiscal (2033B-370 et 2033B-372) | J15: =MAX(0,J11) -> 965.33333 | K15: /!\ Les ammortissement ne peuvent générer du déficit en revanche -----> Ammortissement excédentaire
I16: Amortissement excédentaire : 2033B-318 | J16: =SUM(J3:J8) -> 965.33333
B20: Total | D20: =SUM(D11:D15) -> 89365.333

Sheet Liasse fiscale N+1
D1: Brut | E1: Ammortissement | G1: Net Exercice N+1 | I1: Bilan
A2: ACTIF | B2: Immobilisation corporelle | C2: 2033A-028 | D2: =J2 -> 88400 | E2: 2033A-030 | F2: =J3+'Liasse fiscale N'!J3 -> -6517.3333 | G2: =D2+F2 -> 81882.667 | I2: Immobilisation brut | J2: =Amortissement!$B$3 -> 88400
I3: Amortissement de l'année N+1 2033C-572 et 2033B-254 | J3: =-Amortissement!$F$12 -> -3258.6667
I5: 2033B-218 | J5: =Journal!C15 -> 6600
B6: Disponibilité (La caisse/trésorerie) | C6: 2033A-084 | D6: =J10 -> 8448 | I6: 2033B-242 | J6: =Journal!C16+Journal!C17+Journal!C18+Journal!C19 -> -640
I7: 2033B-244 | J7: =Journal!C20+Journal!C21 -> -868
I8: 2033B-294 | J8: =Journal!C23+Journal!C24+Journal!C22 -> -868
I9: Amortissement excédentaire ( de l'année N) | J9: ='Liasse fiscale N'!J16 -> 965.33333
B10: Total | D10: =D2+F2+D6 -> 90330.667 | I10: Disponibilité | J10: =SUM(J5:J8)+'Liasse fiscale N'!J10 -> 8448
A11: PASSIF | B11: Capital social | D11: =D10-D13-D15 -> 20505 | I11: Résultat comptable (2033B-310) | J11: =SUM(J3:J9) -> 1930.6667
B13: Résultat de l'exercice | D13: =J11 -> 1930.6667
B15: Dette (dette restant dû) | C15: 2033A-156 | D15: 67895 | I15: Résultat fiscal (2033B-370 et 2033B-372) | J15: =MAX(0,J11) -> 1930.6667 | K15: /!\ Les ammortissements ne peuvent générer du déficit en revanche -----> Ammortissement excédentaire
I16: Amortissement excédentaire : 2033B-318 | J16: =MIN(0,SUM(J3:J9)) -> 0
B20: Total | D20: =SUM(D11:D15) -> 90330.667
